<?xml version="1.0" ?>
<robot name="cube" xmlns:xacro="http://www.ros.org/wiki/xacro">

<xacro:include filename="$(find cube_description)/urdf/materials.xacro" />
<xacro:include filename="$(find cube_description)/urdf/cube.trans" />
<xacro:include filename="$(find cube_description)/urdf/gazebo.xacro" />

<link name="base_footprint">
</link>

<joint name="fixed_base_joint" type="fixed">
  <parent link="base_footprint" />
  <child link="base_link" />
</joint>


<link name="base_link">
  <inertial>
    <origin xyz="-0.03436104134763452 0.004255153166517912 0.20134904683591295" rpy="0 0 0"/>
    <mass value="47.20765989840476"/>
    <inertia ixx="1.033748" iyy="1.280415" izz="1.201" ixy="0.031639" iyz="-0.040215" ixz="0.114859"/>
  </inertial>
  <visual>
    <origin xyz="0 0 0" rpy="0 0 0"/>
    <geometry>
      <mesh filename="package://cube_description/meshes/base_link.stl" scale="0.001 0.001 0.001"/>
    </geometry>
    <material name="opaque160160160"/>
  </visual>
  <collision>
    <origin xyz="0 0 0" rpy="0 0 0"/>
    <geometry>
      <mesh filename="package://cube_description/meshes/base_link.stl" scale="0.001 0.001 0.001"/>
    </geometry>
  </collision>
</link>

<link name="imu_v1_1">
  <inertial>
    <origin xyz="0.01122185649964677 0.007537279025856644 0.0010632487781882527" rpy="0 0 0"/>
    <mass value="0.007717572133230737"/>
    <inertia ixx="0.0" iyy="0.0" izz="1e-06" ixy="0.0" iyz="0.0" ixz="-0.0"/>
  </inertial>
  <visual>
    <origin xyz="0.052922 0.082837 -0.2515" rpy="0 0 0"/>
    <geometry>
      <mesh filename="package://cube_description/meshes/imu_v1_1.stl" scale="0.001 0.001 0.001"/>
    </geometry>
    <material name="opaque262626"/>
  </visual>
  <collision>
    <origin xyz="0.052922 0.082837 -0.2515" rpy="0 0 0"/>
    <geometry>
      <mesh filename="package://cube_description/meshes/imu_v1_1.stl" scale="0.001 0.001 0.001"/>
    </geometry>
  </collision>
</link>

<link name="lidar_v1_1">
  <inertial>
    <origin xyz="-0.0006310310009192133 -1.036682722385878e-06 -0.0005403106637103805" rpy="0 0 0"/>
    <mass value="1.347912159118483"/>
    <inertia ixx="0.000658" iyy="0.000639" izz="0.000873" ixy="0.0" iyz="0.0" ixz="7e-06"/>
  </inertial>
  <visual>
    <origin xyz="-0.128043 1.5e-05 -0.1955" rpy="0 0 0"/>
    <geometry>
      <mesh filename="package://cube_description/meshes/lidar_v1_1.stl" scale="0.001 0.001 0.001"/>
    </geometry>
    <material name="steel_satin"/>
  </visual>
  <collision>
    <origin xyz="-0.128043 1.5e-05 -0.1955" rpy="0 0 0"/>
    <geometry>
      <mesh filename="package://cube_description/meshes/lidar_v1_1.stl" scale="0.001 0.001 0.001"/>
    </geometry>
  </collision>
</link>

<link name="depth_camera_v1_1">
  <inertial>
    <origin xyz="0.012822415314312635 0.02438009637633534 -1.0027264107370648e-05" rpy="0 0 0"/>
    <mass value="0.4030868295259092"/>
    <inertia ixx="0.000247" iyy="4.1e-05" izz="0.000247" ixy="6e-06" iyz="-0.0" ixz="-0.0"/>
  </inertial>
  <visual>
    <origin xyz="-0.184088 0.022403 -0.1615" rpy="0 0 0"/>
    <geometry>
      <mesh filename="package://cube_description/meshes/depth_camera_v1_1.stl" scale="0.001 0.001 0.001"/>
    </geometry>
    <material name="steel_satin"/>
  </visual>
  <collision>
    <origin xyz="-0.184088 0.022403 -0.1615" rpy="0 0 0"/>
    <geometry>
      <mesh filename="package://cube_description/meshes/depth_camera_v1_1.stl" scale="0.001 0.001 0.001"/>
    </geometry>
  </collision>
</link>

<link name="left_wheel_v1_1">
  <inertial>
    <origin xyz="-0.00011476068027998013 0.057486019860003096 1.811551186836624e-10" rpy="0 0 0"/>
    <mass value="4.364871932625406"/>
    <inertia ixx="0.007848" iyy="0.014009" izz="0.007848" ixy="-1.2e-05" iyz="-0.0" ixz="0.0"/>
  </inertial>
  <visual>
    <origin xyz="0.014189 -0.115701 -0.08" rpy="0 0 0"/>
    <geometry>
      <mesh filename="package://cube_description/meshes/left_wheel_v1_1.stl" scale="0.001 0.001 0.001"/>
    </geometry>
    <material name="steel_satin"/>
  </visual>
  <collision>
    <origin xyz="0.014189 -0.115701 -0.08" rpy="0 0 0"/>
    <geometry>
      <mesh filename="package://cube_description/meshes/left_wheel_v1_1.stl" scale="0.001 0.001 0.001"/>
    </geometry>
  </collision>
</link>

<link name="right_wheel_v1_1">
  <inertial>
    <origin xyz="0.00011493441134234963 -0.05748636841054998 -1.8113159583332816e-10" rpy="0 0 0"/>
    <mass value="4.364871932625406"/>
    <inertia ixx="0.007848" iyy="0.014009" izz="0.007848" ixy="-1.2e-05" iyz="-0.0" ixz="0.0"/>
  </inertial>
  <visual>
    <origin xyz="0.013725 0.116298 -0.08" rpy="0 0 0"/>
    <geometry>
      <mesh filename="package://cube_description/meshes/right_wheel_v1_1.stl" scale="0.001 0.001 0.001"/>
    </geometry>
    <material name="steel_satin"/>
  </visual>
  <collision>
    <origin xyz="0.013725 0.116298 -0.08" rpy="0 0 0"/>
    <geometry>
      <mesh filename="package://cube_description/meshes/right_wheel_v1_1.stl" scale="0.001 0.001 0.001"/>
    </geometry>
  </collision>
</link>

<joint name="Rigid 1" type="fixed">
  <origin xyz="-0.052922 -0.082837 0.2515" rpy="0 0 0"/>
  <parent link="base_link"/>
  <child link="imu_v1_1"/>
</joint>

<joint name="Rigid 2" type="fixed">
  <origin xyz="0.128043 -1.5e-05 0.1955" rpy="0 0 0"/>
  <parent link="base_link"/>
  <child link="lidar_v1_1"/>
</joint>

<joint name="Rigid 3" type="fixed">
  <origin xyz="0.184088 -0.022403 0.1615" rpy="0 0 0"/>
  <parent link="base_link"/>
  <child link="depth_camera_v1_1"/>
</joint>

<joint name="Revolute 4" type="continuous">
  <origin xyz="-0.014189 0.12 0.08" rpy="0 0 0"/>
  <parent link="base_link"/>
  <child link="left_wheel_v1_1"/>
  <axis xyz="-0.001999 0.999998 0.0"/>
</joint>

<joint name="Revolute 5" type="continuous">
  <origin xyz="-0.013725 -0.12 0.08" rpy="0 0 0"/>
  <parent link="base_link"/>
  <child link="right_wheel_v1_1"/>
  <axis xyz="0.001999 0.999998 -0.0"/>
</joint>

</robot>
